Workbook

Sheet Datos
A1: Tipo de operación | B1: Año | C1: Mes | D1: SCIAN | E1: Clase | F1: Valor en pesos | G1: Valor en dólares
A2: 2 | B2: 2019 | C2: 1 | D2: 311110 | E2: 3111 | F2: 466100000 | G2: 24316759
A3: 2 | B3: 2019 | C3: 1 | D3: 311211 | E3: 3112 | F3: 13722432 | G3: 717785.97
A4: 2 | B4: 2019 | C4: 1 | D4: 311212 | E4: 3112 | F4: 78310853 | G4: 4082726.1
A5: 2 | B5: 2019 | C5: 1 | D5: 311213 | E5: 3112 | F5: 133500000 | G5: 6958889.8
A6: 2 | B6: 2019 | C6: 1 | D6: 311214 | E6: 3112 | F6: 11894489 | G6: 617695.23
A7: 2 | B7: 2019 | C7: 1 | D7: 311215 | E7: 3112 | F7: 1079976 | G7: 56570.97
A8: 2 | B8: 2019 | C8: 1 | D8: 311221 | E8: 3112 | F8: 265500000 | G8: 13857824
A9: 2 | B9: 2019 | C9: 1 | D9: 311222 | E9: 3112 | F9: 275600000 | G9: 14369334
A10: 2 | B10: 2019 | C10: 1 | D10: 311230 | E10: 3112 | F10: 534100000 | G10: 27900168
A11: 2 | B11: 2019 | C11: 1 | D11: 311311 | E11: 3113 | F11: 282000000 | G11: 14692156
A12: 2 | B12: 2019 | C12: 1 | D12: 311319 | E12: 3113 | F12: 67419932 | G12: 3516933.6
A13: 2 | B13: 2019 | C13: 1 | D13: 311340 | E13: 3113 | F13: 959400000 | G13: 50087250
... A25211: 2 | B25211: 2026 | C25211: 7 | D25211: 336992 | E25211: 3369 | F25211: 9635117 | G25211: 550706.39

Sheet TD
A1: Tipo de operación | B1: (Todas)
A3: Suma de Valor en pesos | C3: Clase
A4: Año | B4: Mes | C4: 3111 | D4: 3112 | E4: 3113 | F4: 3114 | G4: 3115 | H4: 3116 | I4: 3117 | J4: 3118 | K4: 3119 | L4: 3121 | M4: 3122 | N4: 3131 | O4: 3132 | P4: 3133 | Q4: 3141 | R4: 3149 | S4: 3151 | T4: 3152 | U4: 3159 | V4: 3161 | W4: 3162 | X4: 3169 | Y4: 3211 | Z4: 3212 | AA4: 3219 | AB4: 3221 | AC4: 3222 | AD4: 3231 | AE4: 3241 | AF4: 3251 | AG4: 3252 | AH4: 3253 | AI4: 3254 | AJ4: 3255 | AK4: 3256 | AL4: 3259 | AM4: 3261 | AN4: 3262 | AO4: 3271 | AP4: 3272 | AQ4: 3273 | AR4: 3274 | AS4: 3279 | AT4: 3311 | AU4: 3312 | AV4: 3313 | AW4: 3314 | AX4: 3315 | AY4: 3321 | AZ4: 3322 | BA4: 3323 | BB4: 3324 | BC4: 3325 | BD4: 3326 | BE4: 3327 | BF4: 3328 | BG4: 3329 | BH4: 3331 | BI4: 3332 | BJ4: 3333 | BK4: 3334 | BL4: 3335 | BM4: 3336 | BN4: 3339 | BO4: 3341 | BP4: 3342 | BQ4: 3343 | BR4: 3344 | BS4: 3345 | BT4: 3346 | BU4: 3351 | BV4: 3352 | BW4: 3353 | BX4: 3359 | BY4: 3361 | BZ4: 3362 | CA4: 3363 | CB4: 3364 | CC4: 3365 | CD4: 3366 | CE4: 3369 | CF4: 3371 | CG4: 3372 | CH4: 3379 | CI4: 3391 | CJ4: 3399
A5: 2019 | B5: 1 | C5: 466100000 | D5: 1313707750 | E5: 2284319932 | F5: 3876980626 | G5: 755474712 | H5: 3240814731 | I5: 1561000000 | J5: 1617800000 | K5: 2458100583 | L5: 9172895294 | M5: 337673207 | N5: 436615800 | O5: 710152987 | P5: 442100000 | Q5: 917100000 | R5: 1110991801 | S5: 809696701 | T5: 4296817620 | U5: 274100000 | V5: 344100000 | W5: 589947950 | X5: 599968413 | Y5: 9189094 | Z5: 47802031 | AA5: 642236172 | AB5: 406283106 | AC5: 2886800000 | AD5: 828888418 | AE5: 4248738094 | AF5: 5486870592 | AG5: 5060013561 | AH5: 1228100000 | AI5: 2393200000 | AJ5: 560800000 | AK5: 4096000000 | AL5: 1810121131 | AM5: 8764562869 | AN5: 3207789970 | AO5: 1707889759 | AP5: 2572575408 | AQ5: 503534938 | AR5: 257564201 | AS5: 751169308 | AT5: 4728000000 | AU5: 1256100000 | AV5: 1073000000 | AW5: 12195900000 | AX5: 424208819 | AY5: 1226000000 | AZ5: 1432554828 | BA5: 1634500000 | BB5: 1172100000 | BC5: 2592000000 | BD5: 1502000000 | BE5: 339631989 | BF5: 592100000 | BG5: 6937500000 | BH5: 2844336532 | BI5: 2843935625 | BJ5: 2471358629 | BK5: 11130000000 | BL5: 941200000 | BM5: 11920000000 | BN5: 8482600000 | BO5: 58830000000 | BP5: 20510000000 | BQ5: 20930000000 | BR5: 11310000000 | BS5: 18784600000 | BT5: 602800000 | BU5: 2295004467 | BV5: 3977500000 | BW5: 19013000000 | BX5: 15878300000 | BY5: 94820000000 | BZ5: 2428000000 | CA5: 76634000000 | CB5: 4978000000 | CC5: 4746000000 | CD5: 1326000000 | CE5: 2458375258 | CF5: 3074220123 | CG5: 365000000 | CH5: 431600000 | CI5: 8930000000 | CJ5: 5202096215
B6: 2 | C6: 498700000 | D6: 1408936789 | E6: 4344300000 | F6: 4658549838 | G6: 785538497 | H6: 3315257446 | I6: 1112000000 | J6: 2163600000 | K6: 2255475700 | L6: 10330306517 | M6: 251551761 | N6: 526039629 | O6: 844366548 | P6: 565100000 | Q6: 1066100000 | R6: 1273922433 | S6: 877267318 | T6: 5152124240 | U6: 338500000 | V6: 521800000 | W6: 793949630 | X6: 636186442 | Y6: 15066808 | Z6: 39006261 | AA6: 744998271 | AB6: 416384096 | AC6: 3142500000 | AD6: 651895882 | AE6: 3263065258 | AF6: 5233270297 | AG6: 4767845045 | AH6: 680000000 | AI6: 2486900000 | AJ6: 518900000 | AK6: 4334000000 | AL6: 1959450338 | AM6: 9132784671 | AN6: 3424178917 | AO6: 2047916053 | AP6: 2568515209 | AQ6: 585748880 | AR6: 236108424 | AS6: 935155775 | AT6: 4281800000 | AU6: 1360500000 | AV6: 946200000 | AW6: 12551700000 | AX6: 416400000 | AY6: 997600000 | AZ6: 1595600342 | BA6: 2224400000 | BB6: 1434000000 | BC6: 2862000000 | BD6: 1493000000 | BE6: 495269901 | BF6: 683300000 | BG6: 8338800000 | BH6: 3902502987 | BI6: 3476828328 | BJ6: 2525260173 | BK6: 14635000000 | BL6: 1200000000 | BM6: 13840000000 | BN6: 10421623464 | BO6: 44260000000 | BP6: 23172000000 | BQ6: 20520000000 | BR6: 9944000000 | BS6: 20657700000 | BT6: 417400000 | BU6: 2792205004 | BV6: 5232000000 | BW6: 21696000000 | BX6: 17566900000 | BY6: 129750000000 | BZ6: 3197000000 | CA6: 84713000000 | CB6: 5372000000 | CC6: 5016000000 | CD6: 1742000000 | CE6: 2390184998 | CF6: 3006879105 | CG6: 312100000 | CH6: 421100000 | CI6: 10641700000 | CJ6: 6294326600
B7: 3 | C7: 517000000 | D7: 1412106924 | E7: 4382400000 | F7: 5334056146 | G7: 963402231 | H7: 3616979042 | I7: 1049000000 | J7: 2474300000 | K7: 2572864441 | L7: 12357878281 | M7: 277446300 | N7: 543212904 | O7: 915670033 | P7: 538100000 | Q7: 1137900000 | R7: 1426575370 | S7: 943567652 | T7: 5425582283 | U7: 368100000 | V7: 438300000 | W7: 814071787 | X7: 677700000 | Y7: 11161063 | Z7: 79394858 | AA7: 743360921 | AB7: 351957151 | AC7: 3312300000 | AD7: 668054026 | AE7: 2606036057 | AF7: 5908255512 | AG7: 5299900000 | AH7: 1394800000 | AI7: 2668600000 | AJ7: 598700000 | AK7: 4744000000 | AL7: 2065320097 | AM7: 10131847079 | AN7: 3765709617 | AO7: 2241956994 | AP7: 2865390103 | AQ7: 637769624 | AR7: 260483938 | AS7: 906211528 | AT7: 5252000000 | AU7: 1394800000 | AV7: 1034000000 | AW7: 12608400000 | AX7: 448305460 | AY7: 1034000000 | AZ7: 1800940482 | BA7: 2342900000 | BB7: 1472600000 | BC7: 2881000000 | BD7: 1780000000 | BE7: 442420736 | BF7: 633500000 | BG7: 8442100000 | BH7: 4087478730 | BI7: 3403245710 | BJ7: 2416148412 | BK7: 16120000000 | BL7: 1036000000 | BM7: 13960000000 | BN7: 11118449355 | BO7: 37510000000 | BP7: 23346000000 | BQ7: 21420000000 | BR7: 11930000000 | BS7: 22584000000 | BT7: 341100000 | BU7: 3630215898 | BV7: 5733500000 | BW7: 24196000000 | BX7: 19420800000 | BY7: 157990000000 | BZ7: 3656000000 | CA7: 88576000000 | CB7: 4664000000 | CC7: 5537000000 | CD7: 1520000000 | CE7: 2855853569 | CF7: 3368018195 | CG7: 351600000 | CH7: 400100000 | CI7: 11813000000 | CJ7: 6392108189
B8: 4 | C8: 612600000 | D8: 1507469273 | E8: 4340928570 | F8: 4923629145 | G8: 1069454637 | H8: 3599591662 | I8: 1246000000 | J8: 2095300000 | K8: 2480780246 | L8: 13260326124 | M8: 254063070 | N8: 473983074 | O8: 896030016 | P8: 427300000 | Q8: 1180900000 | R8: 1324422905 | S8: 1020921589 | T8: 5488041044 | U8: 401600000 | V8: 424900000 | W8: 752090648 | X8: 641947905 | Y8: 27273630 | Z8: 65203116 | AA8: 769972430 | AB8: 356152794 | AC8: 3272700000 | AD8: 677399137 | AE8: 4736318377 | AF8: 6237651688 | AG8: 5087700000 | AH8: 784900000 | AI8: 2422200000 | AJ8: 568800000 | AK8: 4166000000 | AL8: 2194034573 | AM8: 9779330696 | AN8: 3789982545 | AO8: 2168907911 | AP8: 2776173460 | AQ8: 555790208 | AR8: 303738989 | AS8: 1014150889 | AT8: 4951100000 | AU8: 1419200000 | AV8: 1095000000 | AW8: 13387000000 | AX8: 444506809 | AY8: 1241000000 | AZ8: 1748687430 | BA8: 2134200000 | BB8: 1600700000 | BC8: 3106000000 | BD8: 1767000000 | BE8: 431364939 | BF8: 503400000 | BG8: 8506000000 | BH8: 4003837687 | BI8: 3686935139 | BJ8: 2551189338 | BK8: 16105000000 | BL8: 918700000 | BM8: 13620000000 | BN8: 11045858641 | BO8: 57590000000 | BP8: 23583000000 | BQ8: 20360000000 | BR8: 11710000000 | BS8: 22245600000 | BT8: 393400000 | BU8: 3138923871 | BV8: 5312200000 | BW8: 23988000000 | BX8: 19096900000 | BY8: 142990000000 | BZ8: 4222000000 | CA8: 86829000000 | CB8: 5876000000 | CC8: 6592000000 | CD8: 1602000000 | CE8: 3466191397 | CF8: 3229613613 | CG8: 379200000 | CH8: 465000000 | CI8: 11577000000 | CJ8: 6535424081
B9: 5 | C9: 629600000 | D9: 1594014033 | E9: 4594100000 | F9: 4250717518 | G9: 944201176 | H9: 3879918678 | I9: 1067000000 | J9: 2339200000 | K9: 2603595289 | L9: 14017851880 | M9: 329092611 | N9: 520668463 | O9: 968023907 | P9: 476000000 | Q9: 1261000000 | R9: 1488375356 | S9: 1065797643 | T9: 5685394499 | U9: 389000000 | V9: 462900000 | W9: 829566031 | X9: 579516792 | Y9: 28729254 | Z9: 68153703 | AA9: 830378998 | AB9: 485308306 | AC9: 3582600000 | AD9: 719634926 | AE9: 4220382675 | AF9: 6132879261 | AG9: 5298500000 | AH9: 922100000 | AI9: 2826200000 | AJ9: 569500000 | AK9: 4505000000 | AL9: 2329639438 | AM9: 10944419560 | AN9: 4203998583 | AO9: 2334984386 | AP9: 3106914425 | AQ9: 646126297 | AR9: 300024324 | AS9: 1074095991 | AT9: 4587000000 | AU9: 1579200000 | AV9: 1223000000 | AW9: 13519000000 | AX9: 483847132 | AY9: 1247000000 | AZ9: 1902527609 | BA9: 2677900000 | BB9: 1827100000 | BC9: 3173000000 | BD9: 1688000000 | BE9: 463114863 | BF9: 582800000 | BG9: 9102800000 | BH9: 4484598293 | BI9: 4177262000 | BJ9: 2742712415 | BK9: 19735000000 | BL9: 1137000000 | BM9: 15090000000 | BN9: 11522054676 | BO9: 58690000000 | BP9: 29142000000 | BQ9: 24680000000 | BR9: 12550000000 | BS9: 23751500000 | BT9: 363900000 | BU9: 3284800000 | BV9: 5986700000 | BW9: 25123000000 | BX9: 19890200000 | BY9: 148340000000 | BZ9: 4109000000 | CA9: 93195000000 | CB9: 5505000000 | CC9: 6262000000 | CD9: 1483000000 | CE9: 3658322146 | CF9: 3681629436 | CG9: 354200000 | CH9: 580400000 | CI9: 12656000000 | CJ9: 6928591929
B10: 6 | C10: 510400000 | D10: 1534487336 | E10: 3732200000 | F10: 3669457769 | G10: 1031742108 | H10: 3671231073 | I10: 879300000 | J10: 2190500000 | K10: 2327424066 | L10: 14003346928 | M10: 328846925 | N10: 468798101 | O10: 884871325 | P10: 547300000 | Q10: 1163100000 | R10: 1337921938 | S10: 959144621 | T10: 5623367517 | U10: 325000000 | V10: 468600000 | W10: 748517642 | X10: 591216517 | Y10: 16735183 | Z10: 60820483 | AA10: 740369044 | AB10: 406008547 | AC10: 3138000000 | AD10: 704733778 | AE10: 3285004378 | AF10: 5467348253 | AG10: 4674942953 | AH10: 629600000 | AI10: 2610500000 | AJ10: 517400000 | AK10: 4614000000 | AL10: 2090809413 | AM10: 9688136508 | AN10: 3833958186 | AO10: 2056720908 | AP10: 2759323472 | AQ10: 593145013 | AR10: 304580707 | AS10: 1036309499 | AT10: 4846000000 | AU10: 1501300000 | AV10: 1062000000 | AW10: 13071000000 | AX10: 426212070 | AY10: 1083000000 | AZ10: 1642502936 | BA10: 2516800000 | BB10: 1657800000 | BC10: 2939000000 | BD10: 1868000000 | BE10: 387453142 | BF10: 646500000 | BG10: 8075500000 | BH10: 3534955106 | BI10: 3831928109 | BJ10: 2403022235 | BK10: 18555000000 | BL10: 983100000 | BM10: 13400000000 | BN10: 11237700000 | BO10: 53040000000 | BP10: 24625000000 | BQ10: 24380000000 | BR10: 10750000000 | BS10: 21399100000 | BT10: 546800000 | BU10: 4057629143 | BV10: 5358400000 | BW10: 23019000000 | BX10: 18203200000 | BY10: 148650000000 | BZ10: 4208000000 | CA10: 83494000000 | CB10: 5999000000 | CC10: 6036000000 | CD10: 1808000000 | CE10: 2450832842 | CF10: 3425988662 | CG10: 403800000 | CH10: 520200000 | CI10: 11374000000 | CJ10: 6492095140
B11: 7 | C11: 557000000 | D11: 1490575665 | E11: 4193600000 | F11: 3657421546 | G11: 1022525379 | H11: 3873161966 | I11: 1065000000 | J11: 2366700000 | K11: 2527935031 | L11: 13697542971 | M11: 458808219 | N11: 419403071 | O11: 1124674449 | P11: 531400000 | Q11: 1333000000 | R11: 1463807588 | S11: 1039613612 | T11: 5711554259 | U11: 376200000 | V11: 464700000 | W11: 922627888 | X11: 613853070 | Y11: 24550844 | Z11: 71578862 | AA11: 835688005 | AB11: 412814638 | AC11: 3385800000 | AD11: 900673713 | AE11: 3522360634 | AF11: 6144293387 | AG11: 4722636725 | AH11: 776600000 | AI11: 2868900000 | AJ11: 556600000 | AK11: 4841000000 | AL11: 2073595757 | AM11: 10099617109 | AN11: 4056467987 | AO11: 2301294108 | AP11: 3124369897 | AQ11: 671810053 | AR11: 234222367 | AS11: 913916852 | AT11: 5115000000 | AU11: 1327800000 | AV11: 1191000000 | AW11: 13450700000 | AX11: 502623247 | AY11: 1192000000 | AZ11: 1861193761 | BA11: 2878200000 | BB11: 1580400000 | BC11: 3005000000 | BD11: 1645000000 | BE11: 447210830 | BF11: 684900000 | BG11: 8264600000 | BH11: 3685415343 | BI11: 4114833825 | BJ11: 2311617485 | BK11: 17641000000 | BL11: 1008000000 | BM11: 12940000000 | BN11: 10729200702 | BO11: 58720000000 | BP11: 25622000000 | BQ11: 21050000000 | BR11: 12450000000 | BS11: 22173100000 | BT11: 367300000 | BU11: 3286200000 | BV11: 5337000000 | BW11: 24717000000 | BX11: 19849000000 | BY11: 146680000000 | BZ11: 5168000000 | CA11: 80889000000 | CB11: 6762000000 | CC11: 7136000000 | CD11: 427200000 | CE11: 3158574084 | CF11: 3712770280 | CG11: 444200000 | CH11: 624800000 | CI11: 12575000000 | CJ11: 6496033470
B12: 8 | C12: 547400000 | D12: 1520836962 | E12: 4529000000 | F12: 3762480045 | G12: 979675653 | H12: 3768282814 | I12: 1286000000 | J12: 2643000000 | K12: 2494507338 | L12: 11832444765 | M12: 539191516 | N12: 418415500 | O12: 1017823091 | P12: 575400000 | Q12: 1309600000 | R12: 1552923324 | S12: 1125251178 | T12: 5951192487 | U12: 375300000 | V12: 392300000 | W12: 960682020 | X12: 628389440 | Y12: 18724175 | Z12: 82646449 | AA12: 780488506 | AB12: 372425364 | AC12: 3341200000 | AD12: 851782605 | AE12: 3100998886 | AF12: 6342770275 | AG12: 4797466074 | AH12: 799500000 | AI12: 2734500000 | AJ12: 645400000 | AK12: 4707000000 | AL12: 2081642051 | AM12: 10858831179 | AN12: 4178263955 | AO12: 2071607631 | AP12: 2897958635 | AQ12: 657544146 | AR12: 307988098 | AS12: 1117848655 | AT12: 5323000000 | AU12: 1634300000 | AV12: 1177000000 | AW12: 13186200000 | AX12: 430100000 | AY12: 1188000000 | AZ12: 1762331511 | BA12: 3096900000 | BB12: 1894600000 | BC12: 3276000000 | BD12: 1743000000 | BE12: 473725782 | BF12: 761100000 | BG12: 8974000000 | BH12: 3567023800 | BI12: 3826147398 | BJ12: 2760361609 | BK12: 18580000000 | BL12: 956800000 | BM12: 14490000000 | BN12: 11683975989 | BO12: 50240000000 | BP12: 26692000000 | BQ12: 30770000000 | BR12: 12060000000 | BS12: 23500100000 | BT12: 537300000 | BU12: 3633600000 | BV12: 5804900000 | BW12: 25988000000 | BX12: 19837700000 | BY12: 161780000000 | BZ12: 4634000000 | CA12: 99414000000 | CB12: 7367000000 | CC12: 7982000000 | CD12: 680600000 | CE12: 3045307495 | CF12: 3865828584 | CG12: 415700000 | CH12: 592800000 | CI12: 13164000000 | CJ12: 6816925900
B13: 9 | C13: 369200000 | D13: 1388310262 | E13: 4424000000 | F13: 3482274545 | G13: 730913281 | H13: 3697955306 | I13: 1474000000 | J13: 2308600000 | K13: 2421351806 | L13: 12284856528 | M13: 519177527 | N13: 386268461 | O13: 897116691 | P13: 550400000 | Q13: 1297000000 | R13: 1410537501 | S13: 990463084 | T13: 5202999994 | U13: 317300000 | V13: 427900000 | W13: 867497594 | X13: 673381593 | Y13: 15791882 | Z13: 66312372 | AA13: 767782088 | AB13: 300389959 | AC13: 3316100000 | AD13: 727883418 | AE13: 3255014153 | AF13: 5618353223 | AG13: 4597729047 | AH13: 630700000 | AI13: 2403900000 | AJ13: 575000000 | AK13: 4425000000 | AL13: 1822751321 | AM13: 9962836618 | AN13: 3873039015 | AO13: 2083291717 | AP13: 2882117251 | AQ13: 648652036 | AR13: 265328568 | AS13: 902153892 | AT13: 5728000000 | AU13: 1490900000 | AV13: 1138000000 | AW13: 12958000000 | AX13: 404755364 | AY13: 1046000000 | AZ13: 1573934348 | BA13: 3055500000 | BB13: 1344700000 | BC13: 3010000000 | BD13: 1630000000 | BE13: 448053756 | BF13: 530600000 | BG13: 8388200000 | BH13: 3361434446 | BI13: 3746523847 | BJ13: 2406512060 | BK13: 15735000000 | BL13: 958600000 | BM13: 13080000000 | BN13: 11106426330 | BO13: 49020000000 | BP13: 23171000000 | BQ13: 29890000000 | BR13: 12890000000 | BS13: 21677700000 | BT13: 721700000 | BU13: 3122452211 | BV13: 5137400000 | BW13: 24103000000 | BX13: 18599500000 | BY13: 143530000000 | BZ13: 4646000000 | CA13: 92934000000 | CB13: 6081000000 | CC13: 5590000000 | CD13: 684300000 | CE13: 3013778798 | CF13: 3600205095 | CG13: 377600000 | CH13: 538000000 | CI13: 11380000000 | CJ13: 5906969326
B14: 10 | C14: 467100000 | D14: 1555507240 | E14: 3170561739 | F14: 3791645381 | G14: 1027524672 | H14: 4195469489 | I14: 2374000000 | J14: 2395000000 | K14: 2913036593 | L14: 12638236808 | M14: 595576031 | N14: 384476295 | O14: 1036063598 | P14: 653900000 | Q14: 1474000000 | R14: 1515794167 | S14: 1160272136 | T14: 5651342732 | U14: 404900000 | V14: 446900000 | W14: 1000833909 | X14: 730200000 | Y14: 14552597 | Z14: 67374773 | AA14: 914533813 | AB14: 401105317 | AC14: 3626500000 | AD14: 784183662 | AE14: 4408654897 | AF14: 5717135214 | AG14: 4961770657 | AH14: 938700000 | AI14: 3021900000 | AJ14: 662700000 | AK14: 5074000000 | AL14: 2053664768 | AM14: 11214398979 | AN14: 4521217278 | AO14: 2364674590 | AP14: 3210243763 | AQ14: 641803366 | AR14: 295113962 | AS14: 1054878195 | AT14: 4786000000 | AU14: 1457600000 | AV14: 1227000000 | AW14: 12734800000 | AX14: 417000020 | AY14: 1199000000 | AZ14: 1762476644 | BA14: 3056500000 | BB14: 2231100000 | BC14: 3371000000 | BD14: 1486000000 | BE14: 581283814 | BF14: 744000000 | BG14: 9448700000 | BH14: 3628765347 | BI14: 4483300000 | BJ14: 3018403679 | BK14: 18656000000 | BL14: 1069000000 | BM14: 12010000000 | BN14: 11699337992 | BO14: 65910000000 | BP14: 26513000000 | BQ14: 39260000000 | BR14: 12460000000 | BS14: 24166100000 | BT14: 837300000 | BU14: 3294939356 | BV14: 6564400000 | BW14: 26375000000 | BX14: 20383300000 | BY14: 135120000000 | BZ14: 5346000000 | CA14: 93754000000 | CB14: 7975000000 | CC14: 6308000000 | CD14: 1402000000 | CE14: 4217923055 | CF14: 3913564336 | CG14: 475500000 | CH14: 584800000 | CI14: 12820000000 | CJ14: 7230759420
B15: 11 | C15: 412000000 | D15: 1517952270 | E15: 3152741787 | F15: 3375378225 | G15: 910690642 | H15: 4013678887 | I15: 3268000000 | J15: 2518000000 | K15: 2470686462 | L15: 10214153690 | M15: 333550927 | N15: 347862968 | O15: 870250179 | P15: 480600000 | Q15: 1168200000 | R15: 1348649599 | S15: 1046456796 | T15: 4989041127 | U15: 303000000 | V15: 361800000 | W15: 984491172 | X15: 622900000 | Y15: 14479157 | Z15: 65154648 | AA15: 714778160 | AB15: 386099015 | AC15: 2792200000 | AD15: 712393368 | AE15: 1669568871 | AF15: 4742400468 | AG15: 3986933172 | AH15: 730400000 | AI15: 2656400000 | AJ15: 577500000 | AK15: 4458000000 | AL15: 1985534229 | AM15: 9595330061 | AN15: 4046024599 | AO15: 1996976120 | AP15: 2711068887 | AQ15: 618181903 | AR15: 275322678 | AS15: 881394196 | AT15: 4940000000 | AU15: 1435200000 | AV15: 1037000000 | AW15: 12280800000 | AX15: 391903956 | AY15: 1201000000 | AZ15: 1491193574 | BA15: 2843200000 | BB15: 1829400000 | BC15: 2802000000 | BD15: 1483000000 | BE15: 422900000 | BF15: 735700000 | BG15: 8434000000 | BH15: 3252788585 | BI15: 3272542842 | BJ15: 2564917132 | BK15: 14458000000 | BL15: 893800000 | BM15: 12690000000 | BN15: 10371652833 | BO15: 51130000000 | BP15: 21124200000 | BQ15: 33640000000 | BR15: 13000000000 | BS15: 20609900000 | BT15: 867600000 | BU15: 2895255758 | BV15: 4991500000 | BW15: 24358000000 | BX15: 17925400000 | BY15: 137000000000 | BZ15: 3862000000 | CA15: 90774000000 | CB15: 5704000000 | CC15: 6548000000 | CD15: 1534000000 | CE15: 2896723131 | CF15: 3518453685 | CG15: 456700000 | CH15: 477300000 | CI15: 11389000000 | CJ15: 5818831100
B16: 12 | C16: 349100000 | D16: 1477776411 | E16: 2619702162 | F16: 3904402249 | G16: 783133539 | H16: 4389312356 | I16: 2038000000 | J16: 2507000000 | K16: 2631265652 | L16: 10588272173 | M16: 343708578 | N16: 372135296 | O16: 891490983 | P16: 500600000 | Q16: 1263200000 | R16: 1418067275 | S16: 1044289740 | T16: 4994684655 | U16: 355000000 | V16: 421300000 | W16: 957491138 | X16: 568400000 | Y16: 15225676 | Z16: 56136566 | AA16: 816076593 | AB16: 448976352 | AC16: 2939700000 | AD16: 756748223 | AE16: 6263371163 | AF16: 5753102824 | AG16: 4310293146 | AH16: 995900000 | AI16: 2697600000 | AJ16: 536600000 | AK16: 4638000000 | AL16: 1964341773 | AM16: 9878220573 | AN16: 3847381923 | AO16: 1902141417 | AP16: 2823900395 | AQ16: 531862988 | AR16: 259547833 | AS16: 923350672 | AT16: 5165000000 | AU16: 1555200000 | AV16: 1089000000 | AW16: 13238100000 | AX16: 448724064 | AY16: 1052000000 | AZ16: 1744906218 | BA16: 2249400000 | BB16: 1271400000 | BC16: 3030000000 | BD16: 1399000000 | BE16: 484000000 | BF16: 725200000 | BG16: 8426400000 | BH16: 3700666709 | BI16: 4085270101 | BJ16: 2863421060 | BK16: 16591000000 | BL16: 1098000000 | BM16: 11640000000 | BN16: 10687963560 | BO16: 61080000000 | BP16: 25021000000 | BQ16: 22170000000 | BR16: 12870000000 | BS16: 21391700000 | BT16: 639300000 | BU16: 3688178152 | BV16: 5388600000 | BW16: 24617000000 | BX16: 18793600000 | BY16: 131800000000 | BZ16: 3759000000 | CA16: 86357000000 | CB16: 6179000000 | CC16: 5139000000 | CD16: 1506000000 | CE16: 3146024338 | CF16: 3552334921 | CG16: 509800000 | CH16: 493700000 | CI16: 11841000000 | CJ16: 6116588766
A17: 2020 | B17: 1 | C17: 410900000 | D17: 1216464634 | E17: 2792600000 | F17: 3570060782 | G17: 759714114 | H17: 3641113673 | I17: 1244000000 | J17: 2100100000 | K17: 2419640487 | L17: 10124164085 | M17: 249892231 | N17: 344482322 | O17: 709933595 | P17: 446000000 | Q17: 1040500000 | R17: 1087532605 | S17: 836158262 | T17: 3662684847 | U17: 289500000 | V17: 329400000 | W17: 622685422 | X17: 412945954 | Y17: 13048095 | Z17: 51165618 | AA17: 632928072 | AB17: 348708995 | AC17: 2902300000 | AD17: 790056673 | AE17: 3916129773 | AF17: 5642405631 | AG17: 4374238502 | AH17: 785600000 | AI17: 2162000000 | AJ17: 535800000 | AK17: 3982000000 | AL17: 1782889579 | AM17: 8676148898 | AN17: 3550112878 | AO17: 1617555242 | AP17: 2750849944 | AQ17: 601800866 | AR17: 249114578 | AS17: 867573396 | AT17: 5699000000 | AU17: 1538800000 | AV17: 894600000 | AW17: 12029700000 | AX17: 331100000 | AY17: 996600000 | AZ17: 1414485174 | BA17: 1822700000 | BB17: 1198700000 | BC17: 2659000000 | BD17: 1295000000 | BE17: 387254515 | BF17: 607200000 | BG17: 6955400000 | BH17: 2433871899 | BI17: 2837950951 | BJ17: 2431895604 | BK17: 10084000000 | BL17: 746400000 | BM17: 11430000000 | BN17: 8011222779 | BO17: 50870000000 | BP17: 21421000000 | BQ17: 19620000000 | BR17: 10030000000 | BS17: 18258100000 | BT17: 320200000 | BU17: 2093924802 | BV17: 3976500000 | BW17: 19429000000 | BX17: 15308300000 | BY17: 107430000000 | BZ17: 2597000000 | CA17: 77100000000 | CB17: 4730000000 | CC17: 4091000000 | CD17: 762500000 | CE17: 2385221335 | CF17: 3027083659 | CG17: 325200000 | CH17: 390100000 | CI17: 9575000000 | CJ17: 4780543124
B18: 2 | C18: 369000000 | D18: 1323142601 | E18: 3571800000 | F18: 4257479018 | G18: 777967606 | H18: 4001602627 | I18: 1156000000 | J18: 2275500000 | K18: 2373602332 | L18: 11284469194 | M18: 313933645 | N18: 463913332 | O18: 896641474 | P18: 472000000 | Q18: 1087200000 | R18: 1547729768 | S18: 906372252 | T18: 4794984489 | U18: 340300000 | V18: 356100000 | W18: 794865913 | X18: 484018515 | Y18: 25102276 | Z18: 44972135 | AA18: 734997584 | AB18: 426184430 | AC18: 3038400000 | AD18: 667018455 | AE18: 2530581981 | AF18: 5011035301 | AG18: 4298245475 | AH18: 648800000 | AI18: 2029500000 | AJ18: 552400000 | AK18: 3997000000 | AL18: 1891461759 | AM18: 9559179116 | AN18: 3941682070 | AO18: 1999207920 | AP18: 2822050118 | AQ18: 610731067 | AR18: 286244773 | AS18: 863540174 | AT18: 4805300000 | AU18: 1757200000 | AV18: 928400000 | AW18: 11901500000 | AX18: 379200466 | AY18: 928800000 | AZ18: 1514868108 | BA18: 1931800000 | BB18: 1286000000 | BC18: 2959000000 | BD18: 1410000000 | BE18: 501722619 | BF18: 777800000 | BG18: 7920600000 | BH18: 3372247277 | BI18: 3640322407 | BJ18: 2235671605 | BK18: 13915000000 | BL18: 1212000000 | BM18: 13080000000 | BN18: 10373766973 | BO18: 50400000000 | BP18: 20156300000 | BQ18: 20950000000 | BR18: 10500000000 | BS18: 20363600000 | BT18: 357200000 | BU18: 2855970694 | BV18: 4607400000 | BW18: 22657000000 | BX18: 17702300000 | BY18: 132180000000 | BZ18: 2859000000 | CA18: 88648000000 | CB18: 5415000000 | CC18: 4884000000 | CD18: 1353000000 | CE18: 3340323249 | CF18: 3386100000 | CG18: 357100000 | CH18: 426600000 | CI18: 11119000000 | CJ18: 5724464107
B19: 3 | C19: 545100000 | D19: 1836183430 | E19: 4773300000 | F19: 5668699004 | G19: 900390420 | H19: 5130218731 | I19: 1443000000 | J19: 3051000000 | K19: 3405459443 | L19: 15147528490 | M19: 484455950 | N19: 503639573 | O19: 938260195 | P19: 612000000 | Q19: 1437400000 | R19: 1942749690 | S19: 1043622307 | T19: 5541893488 | U19: 425500000 | V19: 543400000 | W19: 830480491 | X19: 604700000 | Y19: 16337797 | Z19: 51784035 | AA19: 963572487 | AB19: 401414098 | AC19: 4112600000 | AD19: 768101575 | AE19: 2880113692 | AF19: 7129381333 | AG19: 5249023279 | AH19: 943500000 | AI19: 3270000000 | AJ19: 706400000 | AK19: 5100000000 | AL19: 2752360938 | AM19: 12326871909 | AN19: 4616954900 | AO19: 2432694313 | AP19: 3458287415 | AQ19: 869234879 | AR19: 315273035 | AS19: 1116999832 | AT19: 6142000000 | AU19: 1721100000 | AV19: 1155000000 | AW19: 16096000000 | AX19: 501052178 | AY19: 1308000000 | AZ19: 1997793057 | BA19: 2790000000 | BB19: 1746300000 | BC19: 3435000000 | BD19: 1909000000 | BE19: 544134595 | BF19: 736000000 | BG19: 9786300000 | BH19: 4444144015 | BI19: 5037746439 | BJ19: 2981823281 | BK19: 18108000000 | BL19: 983400000 | BM19: 15430000000 | BN19: 12858893610 | BO19: 50230000000 | BP19: 24731000000 | BQ19: 23620000000 | BR19: 14310000000 | BS19: 24317800000 | BT19: 407400000 | BU19: 2980117306 | BV19: 5819700000 | BW19: 29180000000 | BX19: 21607200000 | BY19: 173270000000 | BZ19: 3417000000 | CA19: 101020000000 | CB19: 6343000000 | CC19: 5208000000 | CD19: 2216000000 | CE19: 4351875775 | CF19: 4258200000 | CG19: 469700000 | CH19: 533600000 | CI19: 13899000000 | CJ19: 6955126403
B20: 4 | C20: 947600000 | D20: 2198613794 | E20: 6680300000 | F20: 5627970566 | G20: 1310064807 | H20: 5644196244 | I20: 1084000000 | J20: 3113000000 | K20: 3437312549 | L20: 15502549810 | M20: 154455333 | N20: 339998042 | O20: 640346883 | P20: 294733079 | Q20: 647717492 | R20: 2216292566 | S20: 500511837 | T20: 2569716009 | U20: 476300000 | V20: 343200000 | W20: 297752797 | X20: 407751735 | Y20: 14331756 | Z20: 80637217 | AA20: 913750203 | AB20: 551093255 | AC20: 4080400000 | AD20: 651802262 | AE20: 4174469369 | AF20: 6787592952 | AG20: 5365881018 | AH20: 713400000 | AI20: 4095200000 | AJ20: 562800000 | AK20: 6121000000 | AL20: 2643943887 | AM20: 10212652244 | AN20: 1563367046 | AO20: 2392707935 | AP20: 2554796787 | AQ20: 598612379 | AR20: 360056905 | AS20: 1130306564 | AT20: 5609000000 | AU20: 1160500000 | AV20: 1347000000 | AW20: 14767000000 | AX20: 384216496 | AY20: 1638000000 | AZ20: 1708836054 | BA20: 2650900000 | BB20: 2036600000 | BC20: 2003000000 | BD20: 957900000 | BE20: 544553550 | BF20: 705200000 | BG20: 7229500000 | BH20: 2985366471 | BI20: 4941806731 | BJ20: 1700904766 | BK20: 18067000000 | BL20: 1394000000 | BM20: 7149000000 | BN20: 10826196881 | BO20: 62760000000 | BP20: 26500000000 | BQ20: 16110000000 | BR20: 14930000000 | BS20: 19931300000 | BT20: 598200000 | BU20: 4292411275 | BV20: 5581800000 | BW20: 21324000000 | BX20: 18271700000 | BY20: 30743000000 | BZ20: 3316000000 | CA20: 27463000000 | CB20: 3238000000 | CC20: 4753000000 | CD20: 1269000000 | CE20: 1574823178 | CF20: 2417119680 | CG20: 197300000 | CH20: 196179149 | CI20: 13043700000 | CJ20: 4556914886
B21: 5 | C21: 692300000 | D21: 2135421018 | E21: 4154300000 | F21: 4354212850 | G21: 1347805634 | H21: 6823987457 | I21: 1044000000 | J21: 3280000000 | K21: 2991627239 | L21: 10276894657 | M21: 162017001 | N21: 262853348 | O21: 458262336 | P21: 245718679 | Q21: 718059084 | R21: 2352326961 | S21: 412083460 | T21: 2536922191 | U21: 352000000 | V21: 252100000 | W21: 380737786 | X21: 320102066 | Y21: 12508184 | Z21: 58838317 | AA21: 845675864 | AB21: 515417006 | AC21: 3472300000 | AD21: 593580769 | AE21: 3336773866 | AF21: 5485750797 | AG21: 3901274611 | AH21: 578500000 | AI21: 4090300000 | AJ21: 414200000 | AK21: 5105000000 | AL21: 2172761268 | AM21: 8074025221 | AN21: 1169300069 | AO21: 1228293013 | AP21: 2201032662 | AQ21: 698442374 | AR21: 239193556 | AS21: 738848078 | AT21: 4686000000 | AU21: 1318400000 | AV21: 935900000 | AW21: 14687400000 | AX21: 273400010 | AY21: 1269000000 | AZ21: 1462620539 | BA21: 2228600000 | BB21: 2019400000 | BC21: 1278000000 | BD21: 769000000 | BE21: 347352937 | BF21: 892100000 | BG21: 5483200000 | BH21: 2116518358 | BI21: 3832867968 | BJ21: 1216800664 | BK21: 12813000000 | BL21: 1003000000 | BM21: 4177000000 | BN21: 8114313861 | BO21: 47180000000 | BP21: 18158500000 | BQ21: 11140000000 | BR21: 10800000000 | BS21: 14141408687 | BT21: 254900000 | BU21: 2372902407 | BV21: 3648600000 | BW21: 15234000000 | BX21: 12645300000 | BY21: 13629000000 | BZ21: 2372000000 | CA21: 14260300000 | CB21: 3727000000 | CC21: 4165000000 | CD21: 297600000 | CE21: 778016330 | CF21: 2016430385 | CG21: 286500000 | CH21: 235004593 | CI21: 10137900000 | CJ21: 2481046510
B22: 6 | C22: 570200000 | D22: 2128538153 | E22: 4050700000 | F22: 4730197548 | G22: 1539345173 | H22: 6427458073 | I22: 1107000000 | J22: 3182000000 | K22: 3412767694 | L22: 14345249122 | M22: 396202882 | N22: 277744379 | O22: 721496815 | P22: 454600000 | Q22: 1346000000 | R22: 2834417688 | S22: 797992452 | T22: 5018378142 | U22: 499800000 | V22: 318800000 | W22: 709819500 | X22: 527500000 | Y22: 23761106 | Z22: 74549653 | AA22: 1092884648 | AB22: 619933353 | AC22: 3838600000 | AD22: 675758678 | AE22: 1719168475 | AF22: 4646316139 | AG22: 4508454548 | AH22: 685800000 | AI22: 4503200000 | AJ22: 534400000 | AK22: 5418000000 | AL22: 2095913178 | AM22: 11293434920 | AN22: 3199558602 | AO22: 1787972002 | AP22: 2794081793 | AQ22: 861522965 | AR22: 272284967 | AS22: 976379290 | AT22: 4716000000 | AU22: 1318500000 | AV22: 1104000000 | AW22: 14168500000 | AX22: 345800287 | AY22: 1460000000 | AZ22: 1775132520 | BA22: 2854700000 | BB22: 2302200000 | BC22: 2881000000 | BD22: 1631000000 | BE22: 413200000 | BF22: 962100000 | BG22: 7941100000 | BH22: 2808240741 | BI22: 4515055099 | BJ22: 1952834566 | BK22: 20430000000 | BL22: 865100000 | BM22: 10580000000 | BN22: 10732185099 | BO22: 75250000000 | BP22: 25987600000 | BQ22: 30570000000 | BR22: 12870000000 | BS22: 21922700000 | BT22: 443800000 | BU22: 4188003180 | BV22: 6053000000 | BW22: 24936000000 | BX22: 19930000000 | BY22: 117980000000 | BZ22: 3762000000 | CA22: 71040000000 | CB22: 4083000000 | CC22: 4142000000 | CD22: 905000000 | CE22: 2262615774 | CF22: 3486600000 | CG22: 499000000 | CH22: 467200000 | CI22: 12964600000 | CJ22: 5849130265
B23: 7 | C23: 653700000 | D23: 1968750903 | E23: 4031800000 | F23: 3897230518 | G23: 961362414 | H23: 5257450484 | I23: 1158000000 | J23: 2753000000 | K23: 2950628019 | L23: 15800177249 | M23: 513856012 | N23: 309263734 | O23: 949380711 | P23: 533600000 | Q23: 1436300000 | R23: 2458669532 | S23: 951560197 | T23: 5133580780 | U23: 467700000 | V23: 390000000 | W23: 845825943 | X23: 622000000 | Y23: 24844679 | Z23: 61674147 | AA23: 1112461648 | AB23: 442733026 | AC23: 3728500000 | AD23: 757073976 | AE23: 2848097695 | AF23: 5291285356 | AG23: 5119760582 | AH23: 975700000 | AI23: 4318600000 | AJ23: 622000000 | AK23: 5979000000 | AL23: 2372121902 | AM23: 11766993984 | AN23: 4613321582 | AO23: 2327147271 | AP23: 3257532447 | AQ23: 856316156 | AR23: 280441519 | AS23: 977400000 | AT23: 4896000000 | AU23: 1262900000 | AV23: 1234000000 | AW23: 16141900000 | AX23: 309633050 | AY23: 1367000000 | AZ23: 1857003716 | BA23: 2465600000 | BB23: 2155600000 | BC23: 3312000000 | BD23: 1745000000 | BE23: 538500000 | BF23: 1025000000 | BG23: 8818300000 | BH23: 2960227326 | BI23: 3866290910 | BJ23: 2467133922 | BK23: 17832000000 | BL23: 985900000 | BM23: 12570000000 | BN23: 12532876120 | BO23: 66980000000 | BP23: 27733500000 | BQ23: 26330000000 | BR23: 16080000000 | BS23: 22638400000 | BT23: 522800000 | BU23: 3115487968 | BV23: 5709900000 | BW23: 26511000000 | BX23: 22219200000 | BY23: 151750000000 | BZ23: 3722000000 | CA23: 98747000000 | CB23: 3221000000 | CC23: 3430000000 | CD23: 1121000000 | CE23: 2436347665 | CF23: 4118209591 | CG23: 393600000 | CH23: 649200000 | CI23: 13293000000 | CJ23: 6929754379
B24: 8 | C24: 456600000 | D24: 1882183334 | E24: 4112900000 | F24: 4055920956 | G24: 912830811 | H24: 5294837726 | I24: 1467000000 | J24: 2758000000 | K24: 2816376388 | L24: 16689187395 | M24: 501624538 | N24: 358495052 | O24: 1008472174 | P24: 594000000 | Q24: 1512300000 | R24: 2311146772 | S24: 1073105783 | T24: 5491317631 | U24: 434900000 | V24: 445700000 | W24: 804646031 | X24: 720000000 | Y24: 32748398 | Z24: 62327890 | AA24: 1111419492 | AB24: 507415735 | AC24: 3577800000 | AD24: 673521945 | AE24: 3390980446 | AF24: 5433132580 | AG24: 4719057881 | AH24: 985100000 | AI24: 3279700000 | AJ24: 651600000 | AK24: 5239000000 | AL24: 2192200775 | AM24: 12231364068 | AN24: 5234191965 | AO24: 2217215519 | AP24: 3382719154 | AQ24: 942183464 | AR24: 326482476 | AS24: 992060368 | AT24: 3869000000 | AU24: 1479200000 | AV24: 1190000000 | AW24: 14796200000 | AX24: 335499155 | AY24: 1163000000 | AZ24: 1672682631 | BA24: 2463400000 | BB24: 1824500000 | BC24: 3920000000 | BD24: 1762000000 | BE24: 614800000 | BF24: 714600000 | BG24: 10036900000 | BH24: 3204208065 | BI24: 4413439045 | BJ24: 2413257990 | BK24: 19339000000 | BL24: 1083000000 | BM24: 14150000000 | BN24: 12813779412 | BO24: 59360000000 | BP24: 25019300000 | BQ24: 32580000000 | BR24: 14560000000 | BS24: 23148000000 | BT24: 383200000 | BU24: 3800930681 | BV24: 6809100000 | BW24: 28410000000 | BX24: 21337200000 | BY24: 156880000000 | BZ24: 3828000000 | CA24: 104953000000 | CB24: 4518000000 | CC24: 3174000000 | CD24: 331500000 | CE24: 2287789953 | CF24: 4131161214 | CG24: 468300000 | CH24: 654700000 | CI24: 13596000000 | CJ24: 6933563330
B25: 9 | C25: 393400000 | D25: 1922643407 | E25: 3803900000 | F25: 4205860965 | G25: 890621334 | H25: 4858913448 | I25: 1441000000 | J25: 2836000000 | K25: 3039956341 | L25: 16547358430 | M25: 451280820 | N25: 366279954 | O25: 1065630460 | P25: 589100000 | Q25: 1533800000 | R25: 2306876607 | S25: 1286560942 | T25: 5298827229 | U25: 478600000 | V25: 428100000 | W25: 879929990 | X25: 639200000 | Y25: 20025731 | Z25: 82867896 | AA25: 1113201627 | AB25: 477127408 | AC25: 3737600000 | AD25: 769844854 | AE25: 4655952268 | AF25: 6016987345 | AG25: 5186866716 | AH25: 1162200000 | AI25: 2828600000 | AJ25: 695500000 | AK25: 5384000000 | AL25: 2114150122 | AM25: 12422955200 | AN25: 5207996050 | AO25: 2289782081 | AP25: 3462529461 | AQ25: 858867919 | AR25: 319771368 | AS25: 1054753315 | AT25: 5011000000 | AU25: 1046500000 | AV25: 1345000000 | AW25: 15321600000 | AX25: 335753400 | AY25: 1112000000 | AZ25: 1685420090 | BA25: 2747100000 | BB25: 2034700000 | BC25: 3991000000 | BD25: 1773000000 | BE25: 577100000 | BF25: 881100000 | BG25: 9462700000 | BH25: 3306819639 | BI25: 5057085939 | BJ25: 2818278696 | BK25: 19535000000 | BL25: 966200000 | BM25: 13190000000 | BN25: 15138737675 | BO25: 58820000000 | BP25: 27410000000 | BQ25: 40640000000 | BR25: 14420000000 | BS25: 23682900000 | BT25: 703800000 | BU25: 3675911260 | BV25: 6480900000 | BW25: 29170000000 | BX25: 23198700000 | BY25: 160870000000 | BZ25: 4264000000 | CA25: 107049000000 | CB25: 2836000000 | CC25: 3235000000 | CD25: 655200000 | CE25: 4406190309 | CF25: 4173999518 | CG25: 380300000 | CH25: 574000000 | CI25: 14040000000 | CJ25: 7025526350
B26: 10 | C26: 422200000 | D26: 1996519254 | E26: 3224634863 | F26: 4490450622 | G26: 881613340 | H26: 4398673513 | I26: 1781000000 | J26: 3053000000 | K26: 3054286425 | L26: 16673116599 | M26: 522429079 | N26: 383073978 | O26: 1030036652 | P26: 651700000 | Q26: 1627400000 | R26: 2288411565 | S26: 1290380654 | T26: 5675414201 | U26: 491000000 | V26: 439000000 | W26: 913669156 | X26: 619600000 | Y26: 36988451 | Z26: 75228983 | AA26: 1131252612 | AB26: 437207475 | AC26: 3958300000 | AD26: 781930633 | AE26: 3299531582 | AF26: 5929828363 | AG26: 5189700000 | AH26: 1023000000 | AI26: 2897500000 | AJ26: 751900000 | AK26: 6328000000 | AL26: 2416155646 | AM26: 12913161371 | AN26: 5527494455 | AO26: 2589506316 | AP26: 3622639683 | AQ26: 872366105 | AR26: 378033716 | AS26: 1010800000 | AT26: 5130000000 | AU26: 978600000 | AV26: 1353000000 | AW26: 16242000000 | AX26: 353601926 | AY26: 1275000000 | AZ26: 1849297825 | BA26: 3147600000 | BB26: 2068500000 | BC26: 3907000000 | BD26: 1877000000 | BE26: 606600000 | BF26: 912900000 | BG26: 9980600000 | BH26: 3605804589 | BI26: 4829093846 | BJ26: 2628804737 | BK26: 21710000000 | BL26: 1230000000 | BM26: 14600000000 | BN26: 13326855729 | BO26: 71630000000 | BP26: 25643000000 | BQ26: 39670000000 | BR26: 15250000000 | BS26: 26326300000 | BT26: 721900000 | BU26: 3970476924 | BV26: 7644000000 | BW26: 30210000000 | BX26: 23285600000 | BY26: 176340000000 | BZ26: 4016000000 | CA26: 113521000000 | CB26: 3135000000 | CC26: 2947000000 | CD26: 1336000000 | CE26: 4405839728 | CF26: 4441825488 | CG26: 418500000 | CH26: 623600000 | CI26: 14464000000 | CJ26: 7714489764
B27: 11 | C27: 401900000 | D27: 1754242806 | E27: 2789747241 | F27: 4045093327 | G27: 798008669 | H27: 3774159560 | I27: 2082000000 | J27: 2906000000 | K27: 2759452480 | L27: 16844902632 | M27: 329165978 | N27: 348448132 | O27: 1034828819 | P27: 527900000 | Q27: 1582300000 | R27: 1824961298 | S27: 1348182919 | T27: 5419984242 | U27: 415800000 | V27: 368500000 | W27: 939388043 | X27: 678500000 | Y27: 27703191 | Z27: 65031079 | AA27: 1162582845 | AB27: 402221912 | AC27: 3403700000 | AD27: 693682832 | AE27: 1870207071 | AF27: 4495665824 | AG27: 4535842559 | AH27: 827300000 | AI27: 3012500000 | AJ27: 639000000 | AK27: 5084000000 | AL27: 2426512617 | AM27: 11405686994 | AN27: 4789148679 | AO27: 2445031339 | AP27: 3198887376 | AQ27: 876985797 | AR27: 340694478 | AS27: 1034608357 | AT27: 4925000000 | AU27: 748300000 | AV27: 1267000000 | AW27: 16452000000 | AX27: 388824887 | AY27: 1242000000 | AZ27: 1583261094 | BA27: 2544700000 | BB27: 1935400000 | BC27: 3527000000 | BD27: 1698000000 | BE27: 483847703 | BF27: 833300000 | BG27: 8591400000 | BH27: 3563037584 | BI27: 4638920948 | BJ27: 2273964602 | BK27: 18214000000 | BL27: 1068000000 | BM27: 12630000000 | BN27: 12931530123 | BO27: 54540000000 | BP27: 23431000000 | BQ27: 35280000000 | BR27: 15630000000 | BS27: 22080200000 | BT27: 714300000 | BU27: 3222236183 | BV27: 6725300000 | BW27: 25972000000 | BX27: 21385400000 | BY27: 137350000000 | BZ27: 3974000000 | CA27: 98433000000 | CB27: 3256000000 | CC27: 2320000000 | CD27: 1279000000 | CE27: 3530994506 | CF27: 3951971895 | CG27: 408500000 | CH27: 653800000 | CI27: 12573000000 | CJ27: 6469673281
B28: 12 | C28: 593100000 | D28: 1972133076 | E28: 3220700000 | F28: 4701105430 | G28: 915075714 | H28: 4130110022 | I28: 1526000000 | J28: 3091000000 | K28: 3047229603 | L28: 14644663185 | M28: 239972751 | N28: 436163163 | O28: 1108896678 | P28: 583800000 | Q28: 1470300000 | R28: 2084955076 | S28: 1492204073 | T28: 5808037637 | U28: 496300000 | V28: 390000000 | W28: 990533920 | X28: 723900000 | Y28: 32563952 | Z28: 79443918 | AA28: 1212034821 | AB28: 500732458 | AC28: 3833900000 | AD28: 766059961 | AE28: 3331389487 | AF28: 5246553221 | AG28: 4672752047 | AH28: 1069600000 | AI28: 3176600000 | AJ28: 643000000 | AK28: 5905000000 | AL28: 2342530190 | AM28: 11937105738 | AN28: 4681263360 | AO28: 2404363747 | AP28: 3466784829 | AQ28: 790402684 | AR28: 349915779 | AS28: 1113482516 | AT28: 5168000000 | AU28: 871000000 | AV28: 1403000000 | AW28: 16805000000 | AX28: 346355215 | AY28: 1268000000 | AZ28: 1830855604 | BA28: 2673500000 | BB28: 2201000000 | BC28: 3656000000 | BD28: 1859000000 | BE28: 503000000 | BF28: 1084000000 | BG28: 9661500000 | BH28: 3807077771 | BI28: 6115100000 | BJ28: 2650936173 | BK28: 22810000000 | BL28: 1284000000 | BM28: 13420000000 | BN28: 15347499479 | BO28: 63610000000 | BP28: 26456000000 | BQ28: 32390000000 | BR28: 19140000000 | BS28: 25091200000 | BT28: 694200000 | BU28: 3829136625 | BV28: 7542000000 | BW28: 29280000000 | BX28: 24664100000 | BY28: 153280000000 | BZ28: 3831000000 | CA28: 101433000000 | CB28: 4274000000 | CC28: 2191000000 | CD28: 2048000000 | CE28: 3899390957 | CF28: 4577231808 | CG28: 473500000 | CH28: 680400000 | CI28: 14186000000 | CJ28: 7612969426
A29: 2021 | B29: 1 | C29: 564700000 | D29: 1787901153 | E29: 3008600000 | F29: 4099103071 | G29: 909450730 | H29: 3667897800 | I29: 1152000000 | J29: 2284800000 | K29: 2386321600 | L29: 12738133487 | M29: 281423658 | N29: 430709040 | O29: 900852034 | P29: 452400000 | Q29: 1179900000 | R29: 1388263979 | S29: 855534611 | T29: 3959558999 | U29: 317400000 | V29: 322800000 | W29: 643888205 | X29: 399301242 | Y29: 18839139 | Z29: 72606287 | AA29: 878676357 | AB29: 346430398 | AC29: 3074700000 | AD29: 574720098 | AE29: 3071586796 | AF29: 5426524602 | AG29: 4578467811 | AH29: 809700000 | AI29: 2490400000 | AJ29: 602900000 | AK29: 4484000000 | AL29: 1700556977 | AM29: 8962010461 | AN29: 3983203916 | AO29: 1741274433 | AP29: 2816708037 | AQ29: 662268875 | AR29: 310765238 | AS29: 690910754 | AT29: 5053000000 | AU29: 1012800000 | AV29: 1154000000 | AW29: 20451000000 | AX29: 218929619 | AY29: 1041000000 | AZ29: 1468641756 | BA29: 1997100000 | BB29: 1699100000 | BC29: 2588000000 | BD29: 1568000000 | BE29: 400959689 | BF29: 1080000000 | BG29: 6809900000 | BH29: 2690321788 | BI29: 3143788033 | BJ29: 1608654388 | BK29: 10802000000 | BL29: 821800000 | BM29: 10990000000 | BN29: 9105833372 | BO29: 48740000000 | BP29: 20110100000 | BQ29: 14470000000 | BR29: 11750000000 | BS29: 16444200000 | BT29: 438300000 | BU29: 2187198581 | BV29: 4574900000 | BW29: 20289000000 | BX29: 16011800000 | BY29: 124750000000 | BZ29: 2055000000 | CA29: 75612000000 | CB29: 1963000000 | CC29: 2249000000 | CD29: 1390000000 | CE29: 3782660961 | CF29: 3394233011 | CG29: 340700000 | CH29: 516500000 | CI29: 9837000000 | CJ29: 5593883346
B30: 2 | C30: 636300000 | D30: 2050779309 | E30: 3454100000 | F30: 5038694948 | G30: 898011545 | H30: 4724518700 | I30: 1084000000 | J30: 2767000000 | K30: 2665266327 | L30: 13689047560 | M30: 300135005 | N30: 491045024 | O30: 846294257 | P30: 494300000 | Q30: 1490200000 | R30: 1799180763 | S30: 1136213029 | T30: 5029182029 | U30: 409800000 | V30: 420900000 | W30: 759989694 | X30: 541200000 | Y30: 38162286 | Z30: 84274278 | AA30: 1029916403 | AB30: 291169578 | AC30: 3482400000 | AD30: 597421508 | AE30: 3180664176 | AF30: 5917272221 | AG30: 4673846270 | AH30: 638400000 | AI30: 2584200000 | AJ30: 698800000 | AK30: 4754000000 | AL30: 1819575421 | AM30: 10271646521 | AN30: 4366019200 | AO30: 2231706760 | AP30: 3008039907 | AQ30: 614295535 | AR30: 301434312 | AS30: 873356843 | AT30: 5267000000 | AU30: 1204500000 | AV30: 1387000000 | AW30: 20774000000 | AX30: 289100666 | AY30: 1117000000 | AZ30: 1919000000 | BA30: 2692900000 | BB30: 1645500000 | BC30: 3260000000 | BD30: 1708000000 | BE30: 520400000 | BF30: 975200000 | BG30: 8317300000 | BH30: 3781172596 | BI30: 5035450407 | BJ30: 1964534220 | BK30: 18004000000 | BL30: 836100000 | BM30: 13550000000 | BN30: 11981481635 | BO30: 46460000000 | BP30: 21927600000 | BQ30: 22880000000 | BR30: 14270000000 | BS30: 20483600000 | BT30: 343400000 | BU30: 3055847320 | BV30: 6071500000 | BW30: 24452000000 | BX30: 19726200000 | BY30: 124490000000 | BZ30: 3017000000 | CA30: 88570000000 | CB30: 1902000000 | CC30: 1941000000 | CD30: 2360000000 | CE30: 3439914734 | CF30: 4083000000 | CG30: 319300000 | CH30: 609700000 | CI30: 12607000000 | CJ30: 6989030211
B31: 3 | C31: 748100000 | D31: 2594918580 | E31: 4627200000 | F31: 6591359138 | G31: 1096133363 | H31: 6058584141 | I31: 1273000000 | J31: 3191000000 | K31: 3558098601 | L31: 15863873870 | M31: 340313100 | N31: 616522867 | O31: 1202078823 | P31: 624400000 | Q31: 1691700000 | R31: 2385533872 | S31: 1412349885 | T31: 6447480571 | U31: 569700000 | V31: 557600000 | W31: 987457928 | X31: 810800000 | Y31: 38334564 | Z31: 92759307 | AA31: 1437893835 | AB31: 402434470 | AC31: 4276400000 | AD31: 789949854 | AE31: 6113539703 | AF31: 6974619907 | AG31: 5322800000 | AH31: 1307900000 | AI31: 3667900000 | AJ31: 824200000 | AK31: 6169000000 | AL31: 2324266954 | AM31: 13609738553 | AN31: 5603908475 | AO31: 2625695455 | AP31: 3813192142 | AQ31: 902280766 | AR31: 397896792 | AS31: 1178600000 | AT31: 7831000000 | AU31: 1322800000 | AV31: 1872000000 | AW31: 23045000000 | AX31: 348501441 | AY31: 1563000000 | AZ31: 2171200000 | BA31: 3252200000 | BB31: 2168800000 | BC31: 3876000000 | BD31: 2127000000 | BE31: 602100000 | BF31: 1535000000 | BG31: 10959400000 | BH31: 5220161898 | BI31: 6508291696 | BJ31: 2588855650 | BK31: 23550000000 | BL31: 998300000 | BM31: 16660000000 | BN31: 15740011969 | BO31: 55590000000 | BP31: 26876000000 | BQ31: 28440000000 | BR31: 15870000000 | BS31: 26017800000 | BT31: 348300000 | BU31: 3548363722 | BV31: 8366000000 | BW31: 32770000000 | BX31: 26132100000 | BY31: 126790000000 | BZ31: 4556000000 | CA31: 111026000000 | CB31: 3114000000 | CC31: 2549000000 | CD31: 1746000000 | CE31: 4637362705 | CF31: 5232700000 | CG31: 446800000 | CH31: 778600000 | CI31: 15924000000 | CJ31: 8548121543
B32: 4 | C32: 808600000 | D32: 2232330402 | E32: 5087600000 | F32: 5158799012 | G32: 958124859 | H32: 5114565495 | I32: 1334000000 | J32: 2852000000 | K32: 3106093929 | L32: 18263235500 | M32: 233347141 | N32: 546111613 | O32: 1035527747 | P32: 488300000 | Q32: 1707700000 | R32: 1891783946 | S32: 1378390310 | T32: 4948760755 | U32: 499300000 | V32: 438500000 | W32: 844359647 | X32: 813600000 | Y32: 39736157 | Z32: 89733759 | AA32: 1212905018 | AB32: 395628117 | AC32: 3718400000 | AD32: 711395314 | AE32: 5877550992 | AF32: 6333075656 | AG32: 5676894498 | AH32: 966800000 | AI32: 3749200000 | AJ32: 770000000 | AK32: 5319000000 | AL32: 2128978717 | AM32: 12026596435 | AN32: 4797249061 | AO32: 2585713448 | AP32: 3476387688 | AQ32: 818538928 | AR32: 433596767 | AS32: 1006485480 | AT32: 7139000000 | AU32: 1227900000 | AV32: 1770000000 | AW32: 20250000000 | AX32: 296100339 | AY32: 1403000000 | AZ32: 1877002895 | BA32: 2812300000 | BB32: 1815300000 | BC32: 3104000000 | BD32: 2121000000 | BE32: 564500000 | BF32: 1598000000 | BG32: 9005500000 | BH32: 4175730202 | BI32: 5767900000 | BJ32: 1997524395 | BK32: 18252000000 | BL32: 1080000000 | BM32: 14430000000 | BN32: 12918600000 | BO32: 59400000000 | BP32: 23540000000 | BQ32: 24230000000 | BR32: 13430000000 | BS32: 22802100000 | BT32: 416000000 | BU32: 3797192117 | BV32: 6661000000 | BW32: 26948000000 | BX32: 23787000000 | BY32: 150510000000 | BZ32: 4463000000 | CA32: 92750000000 | CB32: 2689000000 | CC32: 2620000000 | CD32: 960700000 | CE32: 3497317892 | CF32: 4282700000 | CG32: 333500000 | CH32: 827700000 | CI32: 14056000000 | CJ32: 8185293706
B33: 5 | C33: 656500000 | D33: 1923599843 | E33: 3933900000 | F33: 4454980745 | G33: 1090255473 | H33: 5774288517 | I33: 1516000000 | J33: 3106000000 | K33: 2871237068 | L33: 16109285353 | M33: 467011228 | N33: 539028094 | O33: 1038339048 | P33: 553000000 | Q33: 1533332569 | R33: 1748245625 | S33: 1335765184 | T33: 5626693270 | U33: 512300000 | V33: 515800000 | W33: 941655355 | X33: 675100000 | Y33: 37236850 | Z33: 117700000 | AA33: 1303154998 | AB33: 402572450 | AC33: 3703500000 | AD33: 767597736 | AE33: 3496350676 | AF33: 5804964026 | AG33: 5194000000 | AH33: 943900000 | AI33: 3486700000 | AJ33: 787500000 | AK33: 4776000000 | AL33: 1983410077 | AM33: 11811445224 | AN33: 4655786473 | AO33: 2341230733 | AP33: 3237517821 | AQ33: 811474050 | AR33: 468209453 | AS33: 1049700000 | AT33: 8609000000 | AU33: 1552700000 | AV33: 1908000000 | AW33: 20690000000 | AX33: 299000000 | AY33: 1368000000 | AZ33: 2077651959 | BA33: 2669400000 | BB33: 1662600000 | BC33: 3111000000 | BD33: 1747000000 | BE33: 586300000 | BF33: 1756000000 | BG33: 9210500000 | BH33: 4013283710 | BI33: 5195900000 | BJ33: 1699050260 | BK33: 19367000000 | BL33: 929100000 | BM33: 13830000000 | BN33: 12761500000 | BO33: 53820000000 | BP33: 23129100000 | BQ33: 26850000000 | BR33: 14800000000 | BS33: 21058100000 | BT33: 518300000 | BU33: 3263288656 | BV33: 6178000000 | BW33: 26894000000 | BX33: 22084600000 | BY33: 155110000000 | BZ33: 4811000000 | CA33: 85711000000 | CB33: 3925000000 | CC33: 2678000000 | CD33: 2751000000 | CE33: 3950946866 | CF33: 4584200000 | CG33: 413600000 | CH33: 710600000 | CI33: 13253000000 | CJ33: 7655274716
B34: 6 | C34: 766700000 | D34: 2287212997 | E34: 3954000000 | F34: 4795108048 | G34: 1049203665 | H34: 6872120933 | I34: 1016000000 | J34: 3083000000 | K34: 3185948258 | L34: 17496293638 | M34: 373615950 | N34: 591412506 | O34: 1019894206 | P34: 569400000 | Q34: 2114200000 | R34: 1858366339 | S34: 1552136096 | T34: 5807776899 | U34: 504800000 | V34: 596800000 | W34: 1183071718 | X34: 676200000 | Y34: 63496066 | Z34: 99838412 | AA34: 1342228200 | AB34: 440315164 | AC34: 3932000000 | AD34: 729044870 | AE34: 4916453100 | AF34: 6992457529 | AG34: 6367300000 | AH34: 1467700000 | AI34: 3656800000 | AJ34: 750100000 | AK34: 5513000000 | AL34: 2057435203 | AM34: 12710476999 | AN34: 4983964135 | AO34: 2783195752 | AP34: 3768776246 | AQ34: 868876470 | AR34: 476495913 | AS34: 1055800000 | AT34: 8694000000 | AU34: 1876600000 | AV34: 2159000000 | AW34: 23361000000 | AX34: 315100535 | AY34: 1501000000 | AZ34: 2183951888 | BA34: 3000200000 | BB34: 1888500000 | BC34: 3323000000 | BD34: 2034000000 | BE34: 557200000 | BF34: 1514000000 | BG34: 9620900000 | BH34: 4166793800 | BI34: 5288987980 | BJ34: 2099393701 | BK34: 20219000000 | BL34: 1037000000 | BM34: 14010000000 | BN34: 14546200000 | BO34: 60460000000 | BP34: 22380500000 | BQ34: 28560000000 | BR34: 14640000000 | BS34: 22284600000 | BT34: 645300000 | BU34: 3859307845 | BV34: 6941000000 | BW34: 28790000000 | BX34: 24260000000 | BY34: 142860000000 | BZ34: 4882000000 | CA34: 85231000000 | CB34: 4462000000 | CC34: 3346000000 | CD34: 7915000000 | CE34: 4274659118 | CF34: 5051500000 | CG34: 449100000 | CH34: 893500000 | CI34: 14478000000 | CJ34: 9136870642
B35: 7 | C35: 651700000 | D35: 2341888960 | E35: 3697700000 | F35: 4410580548 | G35: 1023567751 | H35: 5947322802 | I35: 1605000000 | J35: 3480000000 | K35: 2979367406 | L35: 18451081443 | M35: 412541072 | N35: 517586671 | O35: 1238909210 | P35: 518300000 | Q35: 2197900000 | R35: 1767531415 | S35: 1592327032 | T35: 6059995958 | U35: 535300000 | V35: 550400000 | W35: 1116997015 | X35: 720400000 | Y35: 45697248 | Z35: 126300000 | AA35: 1354531759 | AB35: 434638387 | AC35: 3904600000 | AD35: 805560104 | AE35: 5631511442 | AF35: 7007711379 | AG35: 6220168342 | AH35: 1311600000 | AI35: 3291300000 | AJ35: 736400000 | AK35: 5727000000 | AL35: 2226816287 | AM35: 13090472969 | AN35: 5316840243 | AO35: 2663125481 | AP35: 3522094773 | AQ35: 915600999 | AR35: 414571629 | AS35: 1071200000 | AT35: 8882000000 | AU35: 2296200000 | AV35: 2178000000 | AW35: 20459000000 | AX35: 278941318 | AY35: 1585000000 | AZ35: 2362700000 | BA35: 3080100000 | BB35: 2020300000 | BC35: 3274000000 | BD35: 1933000000 | BE35: 637086802 | BF35: 2467000000 | BG35: 9461900000 | BH35: 3986930593 | BI35: 5561919944 | BJ35: 2355380400 | BK35: 22360000000 | BL35: 1115000000 | BM35: 13680000000 | BN35: 14076588529 | BO35: 57120000000 | BP35: 23523000000 | BQ35: 32000000000 | BR35: 16610000000 | BS35: 23184400000 | BT35: 432600000 | BU35: 3432505545 | BV35: 7559000000 | BW35: 28170000000 | BX35: 24166900000 | BY35: 108120000000 | BZ35: 5227000000 | CA35: 89953000000 | CB35: 5084000000 | CC35: 3910000000 | CD35: 4531000000 | CE35: 3435331049 | CF35: 5237000000 | CG35: 486800000 | CH35: 1030100000 | CI35: 14920000000 | CJ35: 8077863668
B36: 8 | C36: 566900000 | D36: 2424058863 | E36: 3352500000 | F36: 4685157930 | G36: 995030835 | H36: 5797716726 | I36: 1531000000 | J36: 3411000000 | K36: 3085792693 | L36: 18299702043 | M36: 414688575 | N36: 485466695 | O36: 1134200549 | P36: 631900000 | Q36: 1902800000 | R36: 1879556383 | S36: 1517120048 | T36: 5865622426 | U36: 480800000 | V36: 548200000 | W36: 1212925370 | X36: 676100000 | Y36: 48287934 | Z36: 110700000 | AA36: 1482470326 | AB36: 522006316 | AC36: 3809900000 | AD36: 791660494 | AE36: 5361920636 | AF36: 6692717622 | AG36: 6759200000 | AH36: 1494200000 | AI36: 2662900000 | AJ36: 912900000 | AK36: 5857000000 | AL36: 2198486622 | AM36: 13292933225 | AN36: 5437792937 | AO36: 2517835286 | AP36: 3716930388 | AQ36: 822211050 | AR36: 434799532 | AS36: 1218400000 | AT36: 7070000000 | AU36: 2408800000 | AV36: 2306000000 | AW36: 21096000000 | AX36: 355031458 | AY36: 1514000000 | AZ36: 2253400000 | BA36: 3020100000 | BB36: 1898500000 | BC36: 3526000000 | BD36: 2105000000 | BE36: 605366368 | BF36: 2786000000 | BG36: 9715700000 | BH36: 3866963911 | BI36: 5669323964 | BJ36: 2035327031 | BK36: 21110000000 | BL36: 1049000000 | BM36: 13570000000 | BN36: 14228339751 | BO36: 51170000000 | BP36: 22595200000 | BQ36: 33840000000 | BR36: 17870000000 | BS36: 22031100000 | BT36: 561700000 | BU36: 3879387834 | BV36: 6461000000 | BW36: 28420000000 | BX36: 24597800000 | BY36: 110570000000 | BZ36: 5207000000 | CA36: 93535000000 | CB36: 4159000000 | CC36: 5206000000 | CD36: 1051000000 | CE36: 4130453105 | CF36: 5771000000 | CG36: 493200000 | CH36: 1047000000 | CI36: 13535000000 | CJ36: 8306647255
B37: 9 | C37: 568400000 | D37: 2306979415 | E37: 4029000000 | F37: 4278982556 | G37: 866376808 | H37: 5858551383 | I37: 1561000000 | J37: 3277000000 | K37: 3052541088 | L37: 17348085776 | M37: 512328915 | N37: 560274086 | O37: 1144899601 | P37: 547000000 | Q37: 2087000000 | R37: 1797463370 | S37: 1745332008 | T37: 5939732557 | U37: 505800000 | V37: 523700000 | W37: 1235604673 | X37: 776300000 | Y37: 31583222 | Z37: 111200000 | AA37: 1410975654 | AB37: 452218935 | AC37: 3785800000 | AD37: 809632718 | AE37: 6286722103 | AF37: 7508293162 | AG37: 7281400000 | AH37: 787400000 | AI37: 2801500000 | AJ37: 888000000 | AK37: 6016000000 | AL37: 2105867843 | AM37: 13105348110 | AN37: 5212398195 | AO37: 2640235825 | AP37: 3543210273 | AQ37: 777669147 | AR37: 437640343 | AS37: 1015600000 | AT37: 10583000000 | AU37: 2185800000 | AV37: 2583000000 | AW37: 19086000000 | AX37: 318700324 | AY37: 1430000000 | AZ37: 2019500000 | BA37: 3601100000 | BB37: 1963000000 | BC37: 3096000000 | BD37: 1986000000 | BE37: 527891440 | BF37: 2702000000 | BG37: 9592500000 | BH37: 4175169580 | BI37: 5424400000 | BJ37: 2170831707 | BK37: 21450000000 | BL37: 985600000 | BM37: 14250000000 | BN37: 14934825130 | BO37: 62890000000 | BP37: 22123000000 | BQ37: 45550000000 | BR37: 16670000000 | BS37: 23317400000 | BT37: 803600000 | BU37: 3226810892 | BV37: 6890200000 | BW37: 27339000000 | BX37: 24317400000 | BY37: 131020000000 | BZ37: 5866000000 | CA37: 85822000000 | CB37: 4055000000 | CC37: 3379000000 | CD37: 639700000 | CE37: 3238961876 | CF37: 5495700000 | CG37: 474100000 | CH37: 985400000 | CI37: 15222000000 | CJ37: 8116984064
B38: 10 | C38: 549200000 | D38: 2294957634 | E38: 3604725689 | F38: 4673369505 | G38: 1003684137 | H38: 6032684178 | I38: 1892000000 | J38: 3987000000 | K38: 3326972706 | L38: 18562228107 | M38: 435529563 | N38: 592495488 | O38: 1201430078 | P38: 620000000 | Q38: 1961400000 | R38: 1866199755 | S38: 1856922823 | T38: 6105108046 | U38: 496000000 | V38: 485300000 | W38: 1372867333 | X38: 715900000 | Y38: 31163217 | Z38: 162000000 | AA38: 1539009391 | AB38: 623518933 | AC38: 4268000000 | AD38: 888539165 | AE38: 9856933595 | AF38: 7048114869 | AG38: 6578690154 | AH38: 1235000000 | AI38: 3457900000 | AJ38: 931100000 | AK38: 6012000000 | AL38: 2164311428 | AM38: 14363359596 | AN38: 5242097993 | AO38: 2684906113 | AP38: 3752497458 | AQ38: 862517739 | AR38: 491083846 | AS38: 1088600000 | AT38: 9968000000 | AU38: 2121400000 | AV38: 2881000000 | AW38: 19462000000 | AX38: 322600000 | AY38: 1604000000 | AZ38: 2291600000 | BA38: 4370100000 | BB38: 2173600000 | BC38: 3052000000 | BD38: 2227000000 | BE38: 571688636 | BF38: 3417000000 | BG38: 9948400000 | BH38: 3951644098 | BI38: 5622034517 | BJ38: 2095933085 | BK38: 22520000000 | BL38: 1164000000 | BM38: 13710000000 | BN38: 15558200000 | BO38: 65260000000 | BP38: 24653000000 | BQ38: 33290000000 | BR38: 16380000000 | BS38: 23237600000 | BT38: 877300000 | BU38: 3656310506 | BV38: 7467000000 | BW38: 28360000000 | BX38: 25027100000 | BY38: 117250000000 | BZ38: 6249000000 | CA38: 95198000000 | CB38: 3334000000 | CC38: 4604000000 | CD38: 1017000000 | CE38: 2703467384 | CF38: 6081000000 | CG38: 427000000 | CH38: 1277800000 | CI38: 14646000000 | CJ38: 8385724345
B39: 11 | C39: 537500000 | D39: 2608785274 | E39: 3973600000 | F39: 4925379892 | G39: 1074954443 | H39: 6440449085 | I39: 2714000000 | J39: 3879000000 | K39: 3431958772 | L39: 16456579722 | M39: 577863581 | N39: 558449863 | O39: 1243460637 | P39: 620300000 | Q39: 1795700000 | R39: 1896251365 | S39: 1890256560 | T39: 6378476249 | U39: 542700000 | V39: 481300000 | W39: 1513730539 | X39: 792900000 | Y39: 36574020 | Z39: 141100000 | AA39: 1496127785 | AB39: 573214092 | AC39: 4411900000 | AD39: 935801976 | AE39: 7124540858 | AF39: 7863838575 | AG39: 6744700000 | AH39: 1874300000 | AI39: 3525300000 | AJ39: 884200000 | AK39: 6155000000 | AL39: 2175458881 | AM39: 13901059764 | AN39: 5573579918 | AO39: 2731808378 | AP39: 3857523199 | AQ39: 811702238 | AR39: 434355214 | AS39: 1155000000 | AT39: 13836000000 | AU39: 1827600000 | AV39: 2847000000 | AW39: 22431000000 | AX39: 336262697 | AY39: 1790000000 | AZ39: 2195600000 | BA39: 4176700000 | BB39: 2013000000 | BC39: 3511000000 | BD39: 2218000000 | BE39: 524712252 | BF39: 3023000000 | BG39: 9893000000 | BH39: 4399842169 | BI39: 5819700000 | BJ39: 2244414917 | BK39: 22220000000 | BL39: 1057000000 | BM39: 13510000000 | BN39: 15310855241 | BO39: 71690000000 | BP39: 22806800000 | BQ39: 38320000000 | BR39: 16270000000 | BS39: 23149500000 | BT39: 744800000 | BU39: 3848286079 | BV39: 7170000000 | BW39: 28850000000 | BX39: 24868800000 | BY39: 177340000000 | BZ39: 7463000000 | CA39: 97999000000 | CB39: 4047000000 | CC39: 5375000000 | CD39: 1697000000 | CE39: 3133922990 | CF39: 6166200000 | CG39: 455200000 | CH39: 1139100000 | CI39: 14184000000 | CJ39: 8966188956
B40: 12 | C40: 917700000 | D40: 2390674827 | E40: 4222400000 | F40: 5531437380 | G40: 1125088475 | H40: 6145700794 | I40: 1751000000 | J40: 3993000000 | K40: 3619347966 | L40: 20509684304 | M40: 371526016 | N40: 559741928 | O40: 1254473199 | P40: 627900000 | Q40: 1838100000 | R40: 2049839056 | S40: 2377502701 | T40: 7352578173 | U40: 541200000 | V40: 521800000 | W40: 1443925602 | X40: 833800000 | Y40: 34404659 | Z40: 144100000 | AA40: 1580670886 | AB40: 680722683 | AC40: 4647600000 | AD40: 1048196480 | AE40: 9230608222 | AF40: 8869125912 | AG40: 8052700000 | AH40: 1899300000 | AI40: 4130200000 | AJ40: 974400000 | AK40: 7297000000 | AL40: 2146024728 | AM40: 15423577817 | AN40: 5490131791 | AO40: 2980300000 | AP40: 4045672097 | AQ40: 916009406 | AR40: 471699861 | AS40: 1224200000 | AT40: 15422000000 | AU40: 2952500000 | AV40: 3117000000 | AW40: 24478000000 | AX40: 380600000 | AY40: 1714000000 | AZ40: 2412200000 | BA40: 4582200000 | BB40: 2165600000 | BC40: 3692000000 | BD40: 2585000000 | BE40: 755300000 | BF40: 3115000000 | BG40: 10916100000 | BH40: 4989405031 | BI40: 6694700000 | BJ40: 2400925796 | BK40: 25560000000 | BL40: 1142000000 | BM40: 14560000000 | BN40: 18240451418 | BO40: 81160000000 | BP40: 25907000000 | BQ40: 41220000000 | BR40: 22410000000 | BS40: 26981400000 | BT40: 648800000 | BU40: 3893017664 | BV40: 8918000000 | BW40: 32960000000 | BX40: 28980500000 | BY40: 149360000000 | BZ40: 6265000000 | CA40: 102634000000 | CB40: 4048000000 | CC40: 6025000000 | CD40: 2564000000 | CE40: 3662855030 | CF40: 6788600000 | CG40: 588400000 | CH40: 1248400000 | CI40: 15458000000 | CJ40: 9688987635
